Workbook

Sheet Raw Vote Data
A1: Year | B1: Winner | C1: Party | D1: % | E1: Margin% | F1: Votes | G1: Margin2 | H1: Runner-up | I1: Party3 | J1: RU Votes | K1: Turnout | L1: Total Vote
A2: 1912 | B2: Woodrow Wilson | C2: Dem. | D2: 0.4184 | E2: 0.1444 | F2: 6296284 | G2: 2173563 | H2: Theodore Roosevelt | I2: Prog. | J2: =Table1[[#This Row],[Votes]]-Table1[[#This Row],[Margin2]] -> 4122721 | K2: 0.59 | L2: =Table1[[#This Row],[RU Votes]]+Table1[[#This Row],[Votes]] -> 10419005
A3: 1916 | B3: Woodrow Wilson | C3: Dem. | D3: 0.4924 | E3: 0.0312 | F3: 9126868 | G3: 578140 | H3: Charles Evans Hughes | I3: Rep. | J3: =Table1[[#This Row],[Votes]]-Table1[[#This Row],[Margin2]] -> 8548728 | K3: 0.618 | L3: =Table1[[#This Row],[RU Votes]]+Table1[[#This Row],[Votes]] -> 17675596
A4: 1920 | B4: Warren G. Harding | C4: Rep. | D4: 0.6032 | E4: 0.2617 | F4: 16144093 | G4: 7004432 | H4: James M. Cox | I4: Dem. | J4: =Table1[[#This Row],[Votes]]-Table1[[#This Row],[Margin2]] -> 9139661 | K4: 0.492 | L4: =Table1[[#This Row],[RU Votes]]+Table1[[#This Row],[Votes]] -> 25283754
A5: 1924 | B5: Calvin Coolidge | C5: Rep. | D5: 0.5404 | E5: 0.2522 | F5: 15723789 | G5: 7337547 | H5: John W. Davis | I5: Dem. | J5: =Table1[[#This Row],[Votes]]-Table1[[#This Row],[Margin2]] -> 8386242 | K5: 0.489 | L5: =Table1[[#This Row],[RU Votes]]+Table1[[#This Row],[Votes]] -> 24110031
A6: 1928 | B6: Herbert Hoover | C6: Rep. | D6: 0.5821 | E6: 0.1741 | F6: 21427123 | G6: 6411659 | H6: Al Smith | I6: Dem. | J6: =Table1[[#This Row],[Votes]]-Table1[[#This Row],[Margin2]] -> 15015464 | K6: 0.569 | L6: =Table1[[#This Row],[RU Votes]]+Table1[[#This Row],[Votes]] -> 36442587
A7: 1932 | B7: Franklin D. Roosevelt | C7: Dem. | D7: 0.5741 | E7: 0.1776 | F7: 22821277 | G7: 7060023 | H7: Herbert Hoover | I7: Rep. | J7: =Table1[[#This Row],[Votes]]-Table1[[#This Row],[Margin2]] -> 15761254 | K7: 0.569 | L7: =Table1[[#This Row],[RU Votes]]+Table1[[#This Row],[Votes]] -> 38582531
A8: 1936 | B8: Franklin D. Roosevelt | C8: Dem. | D8: 0.608 | E8: 0.2426 | F8: 27752648 | G8: 11070786 | H8: Alf Landon | I8: Rep. | J8: =Table1[[#This Row],[Votes]]-Table1[[#This Row],[Margin2]] -> 16681862 | K8: 0.61 | L8: =Table1[[#This Row],[RU Votes]]+Table1[[#This Row],[Votes]] -> 44434510
A9: 1940 | B9: Franklin D. Roosevelt | C9: Dem. | D9: 0.5474 | E9: 0.0996 | F9: 27313945 | G9: 4966201 | H9: Wendell Willkie | I9: Rep. | J9: =Table1[[#This Row],[Votes]]-Table1[[#This Row],[Margin2]] -> 22347744 | K9: 0.624 | L9: =Table1[[#This Row],[RU Votes]]+Table1[[#This Row],[Votes]] -> 49661689
A10: 1944 | B10: Franklin D. Roosevelt | C10: Dem. | D10: 0.5339 | E10: 0.075 | F10: 25612916 | G10: 3594987 | H10: Thomas E. Dewey | I10: Rep. | J10: =Table1[[#This Row],[Votes]]-Table1[[#This Row],[Margin2]] -> 22017929 | K10: 0.559 | L10: =Table1[[#This Row],[RU Votes]]+Table1[[#This Row],[Votes]] -> 47630845
A11: 1948 | B11: Harry S Truman | C11: Dem. | D11: 0.4955 | E11: 0.0448 | F11: 24179347 | G11: 2188055 | H11: Thomas E. Dewey | I11: Rep. | J11: =Table1[[#This Row],[Votes]]-Table1[[#This Row],[Margin2]] -> 21991292 | K11: 0.522 | L11: =Table1[[#This Row],[RU Votes]]+Table1[[#This Row],[Votes]] -> 46170639
A12: 1952 | B12: Dwight D. Eisenhower | C12: Rep. | D12: 0.5518 | E12: 0.1085 | F12: 34075529 | G12: 6700439 | H12: Adlai Stevenson II | I12: Dem. | J12: =Table1[[#This Row],[Votes]]-Table1[[#This Row],[Margin2]] -> 27375090 | K12: 0.623 | L12: =Table1[[#This Row],[RU Votes]]+Table1[[#This Row],[Votes]] -> 61450619
A13: 1956 | B13: Dwight D. Eisenhower | C13: Rep. | D13: 0.5737 | E13: 0.154 | F13: 35579180 | G13: 9551152 | H13: Adlai Stevenson II | I13: Dem. | J13: =Table1[[#This Row],[Votes]]-Table1[[#This Row],[Margin2]] -> 26028028 | K13: 0.602 | L13: =Table1[[#This Row],[RU Votes]]+Table1[[#This Row],[Votes]] -> 61607208
... A29: 2020 | B29: Joe Biden | C29: Dem. | D29: 0.5131 | E29: 0.0445 | F29: 81283501 | G29: 7059526 | H29: Donald Trump | I29: Rep. | J29: =Table1[[#This Row],[Votes]]-Table1[[#This Row],[Margin2]] -> 74223975 | K29: 0.666 | L29: =Table1[[#This Row],[RU Votes]]+Table1[[#This Row],[Votes]] -> 155507476
A30: 2024 | B30: Donald Trump | C30: Rep. | F30: 74834590 | G30: =Table1[[#This Row],[Votes]]-G33 -> 3594735 | H30: Kamala Harris | I30: Dem. | J30: =Table1[[#This Row],[Votes]]-Table1[[#This Row],[Margin2]] -> 71239855 | L30: =Table1[[#This Row],[RU Votes]]+Table1[[#This Row],[Votes]] -> 146074445
G33: 71239855

Sheet DR Breakdown
A1: Year | B1: Dem. | C1: Rep. | D1: Total | F1: Dem | I1: Rep | L1: Total
A2: 1912 | B2: =IF(Table1[[#This Row],[Party]]=Table2[[#Headers],[Dem.]],Table1[[#This Row],[Votes]],Table1[[#This Row],[RU Votes]]) -> 6296284 | C2: =IF(Table1[[#This Row],[Party]]=Table2[[#Headers],[Rep.]],Table1[[#This Row],[Votes]],Table1[[#This Row],[RU Votes]]) -> 4122721 | D2: =Table2[[#This Row],[Rep.]]+Table2[[#This Row],[Dem.]] -> 10419005 | F2: Stat | G2: Value | I2: Stat | J2: Value | L2: Stat | M2: Value
A3: 1916 | B3: =IF(Table1[[#This Row],[Party]]=Table2[[#Headers],[Dem.]],Table1[[#This Row],[Votes]],Table1[[#This Row],[RU Votes]]) -> 9126868 | C3: =IF(Table1[[#This Row],[Party]]=Table2[[#Headers],[Rep.]],Table1[[#This Row],[Votes]],Table1[[#This Row],[RU Votes]]) -> 8548728 | D3: =Table2[[#This Row],[Rep.]]+Table2[[#This Row],[Dem.]] -> 17675596 | F3: Min | G3: =MIN(Table2[Dem.]) -> 6296284 | I3: Min | J3: =MIN(Table2[Rep.]) -> 4122721 | L3: Min | M3: =MIN(Table2[Total]) -> 10419005
A4: 1920 | B4: =IF(Table1[[#This Row],[Party]]=Table2[[#Headers],[Dem.]],Table1[[#This Row],[Votes]],Table1[[#This Row],[RU Votes]]) -> 9139661 | C4: =IF(Table1[[#This Row],[Party]]=Table2[[#Headers],[Rep.]],Table1[[#This Row],[Votes]],Table1[[#This Row],[RU Votes]]) -> 16144093 | D4: =Table2[[#This Row],[Rep.]]+Table2[[#This Row],[Dem.]] -> 25283754 | F4: Q1 | G4: =_xlfn.QUARTILE.INC(Table2[Dem.],1) -> 25612916 | I4: Q1 | J4: =_xlfn.QUARTILE.INC(Table2[Rep.],1) -> 21991292 | L4: Q1 | M4: =_xlfn.QUARTILE.INC(Table2[Total],1) -> 46170639
A5: 1924 | B5: =IF(Table1[[#This Row],[Party]]=Table2[[#Headers],[Dem.]],Table1[[#This Row],[Votes]],Table1[[#This Row],[RU Votes]]) -> 8386242 | C5: =IF(Table1[[#This Row],[Party]]=Table2[[#Headers],[Rep.]],Table1[[#This Row],[Votes]],Table1[[#This Row],[RU Votes]]) -> 15723789 | D5: =Table2[[#This Row],[Rep.]]+Table2[[#This Row],[Dem.]] -> 24110031 | F5: Median | G5: =MEDIAN(Table2[Dem.]) -> 34220984 | I5: Median | J5: =MEDIAN(Table2[Rep.]) -> 35579180 | L5: Median | M5: =MEDIAN(Table2[Total]) -> 70304794
A6: 1928 | B6: =IF(Table1[[#This Row],[Party]]=Table2[[#Headers],[Dem.]],Table1[[#This Row],[Votes]],Table1[[#This Row],[RU Votes]]) -> 15015464 | C6: =IF(Table1[[#This Row],[Party]]=Table2[[#Headers],[Rep.]],Table1[[#This Row],[Votes]],Table1[[#This Row],[RU Votes]]) -> 21427123 | D6: =Table2[[#This Row],[Rep.]]+Table2[[#This Row],[Dem.]] -> 36442587 | F6: Q3 | G6: =_xlfn.QUARTILE.INC(Table2[Dem.],3) -> 47401185 | I6: Q3 | J6: =_xlfn.QUARTILE.INC(Table2[Rep.],3) -> 50456002 | L6: Q3 | M6: =_xlfn.QUARTILE.INC(Table2[Total],3) -> 92032824
A7: 1932 | B7: =IF(Table1[[#This Row],[Party]]=Table2[[#Headers],[Dem.]],Table1[[#This Row],[Votes]],Table1[[#This Row],[RU Votes]]) -> 22821277 | C7: =IF(Table1[[#This Row],[Party]]=Table2[[#Headers],[Rep.]],Table1[[#This Row],[Votes]],Table1[[#This Row],[RU Votes]]) -> 15761254 | D7: =Table2[[#This Row],[Rep.]]+Table2[[#This Row],[Dem.]] -> 38582531 | F7: Max | G7: =MAX(Table2[Dem.]) -> 81283501 | I7: Max | J7: =MAX(Table2[Rep.]) -> 74834590 | L7: Max | M7: =MAX(Table2[Total]) -> 155507476
A8: 1936 | B8: =IF(Table1[[#This Row],[Party]]=Table2[[#Headers],[Dem.]],Table1[[#This Row],[Votes]],Table1[[#This Row],[RU Votes]]) -> 27752648 | C8: =IF(Table1[[#This Row],[Party]]=Table2[[#Headers],[Rep.]],Table1[[#This Row],[Votes]],Table1[[#This Row],[RU Votes]]) -> 16681862 | D8: =Table2[[#This Row],[Rep.]]+Table2[[#This Row],[Dem.]] -> 44434510 | F8: Mean | G8: =AVERAGE(Table2[Dem.]) -> 37195630 | I8: Mean | J8: =AVERAGE(Table2[Rep.]) -> 37406049 | L8: Mean | M8: =AVERAGE(Table2[Total]) -> 74601680
A9: 1940 | B9: =IF(Table1[[#This Row],[Party]]=Table2[[#Headers],[Dem.]],Table1[[#This Row],[Votes]],Table1[[#This Row],[RU Votes]]) -> 27313945 | C9: =IF(Table1[[#This Row],[Party]]=Table2[[#Headers],[Rep.]],Table1[[#This Row],[Votes]],Table1[[#This Row],[RU Votes]]) -> 22347744 | D9: =Table2[[#This Row],[Rep.]]+Table2[[#This Row],[Dem.]] -> 49661689 | F9: Std Dev | G9: =_xlfn.STDEV.S(Table2[Dem.]) -> 20331383 | I9: Std Dev | J9: =_xlfn.STDEV.S(Table2[Rep.]) -> 19546185 | L9: Std Dev | M9: =_xlfn.STDEV.S(Table2[Total]) -> 39078684
A10: 1944 | B10: =IF(Table1[[#This Row],[Party]]=Table2[[#Headers],[Dem.]],Table1[[#This Row],[Votes]],Table1[[#This Row],[RU Votes]]) -> 25612916 | C10: =IF(Table1[[#This Row],[Party]]=Table2[[#Headers],[Rep.]],Table1[[#This Row],[Votes]],Table1[[#This Row],[RU Votes]]) -> 22017929 | D10: =Table2[[#This Row],[Rep.]]+Table2[[#This Row],[Dem.]] -> 47630845 | F10: IQR | G10: =G6-G4 -> 21788269 | I10: IQR | J10: =J6-J4 -> 28464710 | L10: IQR | M10: =M6-M4 -> 45862185
A11: 1948 | B11: =IF(Table1[[#This Row],[Party]]=Table2[[#Headers],[Dem.]],Table1[[#This Row],[Votes]],Table1[[#This Row],[RU Votes]]) -> 24179347 | C11: =IF(Table1[[#This Row],[Party]]=Table2[[#Headers],[Rep.]],Table1[[#This Row],[Votes]],Table1[[#This Row],[RU Votes]]) -> 21991292 | D11: =Table2[[#This Row],[Rep.]]+Table2[[#This Row],[Dem.]] -> 46170639 | F11: LF | G11: =G4-(G10*1.5) -> -7069487.5 | I11: LF | J11: =J4-(J10*1.5) -> -20705773 | L11: LF | M11: =M4-(M10*1.5) -> -22622638
A12: 1952 | B12: =IF(Table1[[#This Row],[Party]]=Table2[[#Headers],[Dem.]],Table1[[#This Row],[Votes]],Table1[[#This Row],[RU Votes]]) -> 27375090 | C12: =IF(Table1[[#This Row],[Party]]=Table2[[#Headers],[Rep.]],Table1[[#This Row],[Votes]],Table1[[#This Row],[RU Votes]]) -> 34075529 | D12: =Table2[[#This Row],[Rep.]]+Table2[[#This Row],[Dem.]] -> 61450619 | F12: UF | G12: =G6+(G10*1.5) -> 80083588 | I12: UF | J12: =J6+(J10*1.5) -> 93153067 | L12: UF | M12: =M6+(M10*1.5) -> 1.608261e+08
A13: 1956 | B13: =IF(Table1[[#This Row],[Party]]=Table2[[#Headers],[Dem.]],Table1[[#This Row],[Votes]],Table1[[#This Row],[RU Votes]]) -> 26028028 | C13: =IF(Table1[[#This Row],[Party]]=Table2[[#Headers],[Rep.]],Table1[[#This Row],[Votes]],Table1[[#This Row],[RU Votes]]) -> 35579180 | D13: =Table2[[#This Row],[Rep.]]+Table2[[#This Row],[Dem.]] -> 61607208
A14: 1960 | B14: =IF(Table1[[#This Row],[Party]]=Table2[[#Headers],[Dem.]],Table1[[#This Row],[Votes]],Table1[[#This Row],[RU Votes]]) -> 34220984 | C14: =IF(Table1[[#This Row],[Party]]=Table2[[#Headers],[Rep.]],Table1[[#This Row],[Votes]],Table1[[#This Row],[RU Votes]]) -> 34108157 | D14: =Table2[[#This Row],[Rep.]]+Table2[[#This Row],[Dem.]] -> 68329141
A15: 1964 | B15: =IF(Table1[[#This Row],[Party]]=Table2[[#Headers],[Dem.]],Table1[[#This Row],[Votes]],Table1[[#This Row],[RU Votes]]) -> 43129040 | C15: =IF(Table1[[#This Row],[Party]]=Table2[[#Headers],[Rep.]],Table1[[#This Row],[Votes]],Table1[[#This Row],[RU Votes]]) -> 27175754 | D15: =Table2[[#This Row],[Rep.]]+Table2[[#This Row],[Dem.]] -> 70304794
A16: 1968 | B16: =IF(Table1[[#This Row],[Party]]=Table2[[#Headers],[Dem.]],Table1[[#This Row],[Votes]],Table1[[#This Row],[RU Votes]]) -> 31271839 | C16: =IF(Table1[[#This Row],[Party]]=Table2[[#Headers],[Rep.]],Table1[[#This Row],[Votes]],Table1[[#This Row],[RU Votes]]) -> 31783783 | D16: =Table2[[#This Row],[Rep.]]+Table2[[#This Row],[Dem.]] -> 63055622
A17: 1972 | B17: =IF(Table1[[#This Row],[Party]]=Table2[[#Headers],[Dem.]],Table1[[#This Row],[Votes]],Table1[[#This Row],[RU Votes]]) -> 29173222 | C17: =IF(Table1[[#This Row],[Party]]=Table2[[#Headers],[Rep.]],Table1[[#This Row],[Votes]],Table1[[#This Row],[RU Votes]]) -> 47168710 | D17: =Table2[[#This Row],[Rep.]]+Table2[[#This Row],[Dem.]] -> 76341932
A18: 1976 | B18: =IF(Table1[[#This Row],[Party]]=Table2[[#Headers],[Dem.]],Table1[[#This Row],[Votes]],Table1[[#This Row],[RU Votes]]) -> 40831881 | C18: =IF(Table1[[#This Row],[Party]]=Table2[[#Headers],[Rep.]],Table1[[#This Row],[Votes]],Table1[[#This Row],[RU Votes]]) -> 39148634 | D18: =Table2[[#This Row],[Rep.]]+Table2[[#This Row],[Dem.]] -> 79980515
A19: 1980 | B19: =IF(Table1[[#This Row],[Party]]=Table2[[#Headers],[Dem.]],Table1[[#This Row],[Votes]],Table1[[#This Row],[RU Votes]]) -> 35481115 | C19: =IF(Table1[[#This Row],[Party]]=Table2[[#Headers],[Rep.]],Table1[[#This Row],[Votes]],Table1[[#This Row],[RU Votes]]) -> 43903230 | D19: =Table2[[#This Row],[Rep.]]+Table2[[#This Row],[Dem.]] -> 79384345
A20: 1984 | B20: =IF(Table1[[#This Row],[Party]]=Table2[[#Headers],[Dem.]],Table1[[#This Row],[Votes]],Table1[[#This Row],[RU Votes]]) -> 37577352 | C20: =IF(Table1[[#This Row],[Party]]=Table2[[#Headers],[Rep.]],Table1[[#This Row],[Votes]],Table1[[#This Row],[RU Votes]]) -> 54455472 | D20: =Table2[[#This Row],[Rep.]]+Table2[[#This Row],[Dem.]] -> 92032824
A21: 1988 | B21: =IF(Table1[[#This Row],[Party]]=Table2[[#Headers],[Dem.]],Table1[[#This Row],[Votes]],Table1[[#This Row],[RU Votes]]) -> 41809476 | C21: =IF(Table1[[#This Row],[Party]]=Table2[[#Headers],[Rep.]],Table1[[#This Row],[Votes]],Table1[[#This Row],[RU Votes]]) -> 48886597 | D21: =Table2[[#This Row],[Rep.]]+Table2[[#This Row],[Dem.]] -> 90696073
A22: 1992 | B22: =IF(Table1[[#This Row],[Party]]=Table2[[#Headers],[Dem.]],Table1[[#This Row],[Votes]],Table1[[#This Row],[RU Votes]]) -> 44909889 | C22: =IF(Table1[[#This Row],[Party]]=Table2[[#Headers],[Rep.]],Table1[[#This Row],[Votes]],Table1[[#This Row],[RU Votes]]) -> 39104550 | D22: =Table2[[#This Row],[Rep.]]+Table2[[#This Row],[Dem.]] -> 84014439
A23: 1996 | B23: =IF(Table1[[#This Row],[Party]]=Table2[[#Headers],[Dem.]],Table1[[#This Row],[Votes]],Table1[[#This Row],[RU Votes]]) -> 47401185 | C23: =IF(Table1[[#This Row],[Party]]=Table2[[#Headers],[Rep.]],Table1[[#This Row],[Votes]],Table1[[#This Row],[RU Votes]]) -> 39197469 | D23: =Table2[[#This Row],[Rep.]]+Table2[[#This Row],[Dem.]] -> 86598654
A24: 2000 | B24: =IF(Table1[[#This Row],[Party]]=Table2[[#Headers],[Dem.]],Table1[[#This Row],[Votes]],Table1[[#This Row],[RU Votes]]) -> 50999897 | C24: =IF(Table1[[#This Row],[Party]]=Table2[[#Headers],[Rep.]],Table1[[#This Row],[Votes]],Table1[[#This Row],[RU Votes]]) -> 50456002 | D24: =Table2[[#This Row],[Rep.]]+Table2[[#This Row],[Dem.]] -> 101455899
... A30: 2024 | B30: =IF(Table1[[#This Row],[Party]]=Table2[[#Headers],[Dem.]],Table1[[#This Row],[Votes]],Table1[[#This Row],[RU Votes]]) -> 71239855 | C30: =IF(Table1[[#This Row],[Party]]=Table2[[#Headers],[Rep.]],Table1[[#This Row],[Votes]],Table1[[#This Row],[RU Votes]]) -> 74834590 | D30: =Table2[[#This Row],[Rep.]]+Table2[[#This Row],[Dem.]] -> 146074445

Sheet Z Scores
A1: Year | B1: Dem. | C1: DZ-Score | D1: DZ Dif | E1: Rep. | F1: RZ-Score | G1: RZ Dif | H1: Total | I1: TZ-Score | K1: Votes are displayed in millions
A2: 1912 | B2: 6296284 | C2: =(Table4[[#This Row],[Dem.]]-'DR Breakdown'!$G$8)/'DR Breakdown'!$G$9 -> -1.5197857 | D2: =IFERROR(Table4[[#This Row],[DZ-Score]]-C1,"-") -> - | E2: 4122721 | F2: =(Table4[[#This Row],[Rep.]]-'DR Breakdown'!$J$8)/'DR Breakdown'!$J$9 -> -1.7028043 | G2: =IFERROR(Table4[[#This Row],[RZ-Score]]-F1,"-") -> - | H2: 10419005 | I2: =(Table4[[#This Row],[Total]]-'DR Breakdown'!$M$8)/'DR Breakdown'!$M$9 -> -1.642396
A3: 1916 | B3: 9126868 | C3: =(Table4[[#This Row],[Dem.]]-'DR Breakdown'!$G$8)/'DR Breakdown'!$G$9 -> -1.3805633 | D3: =IFERROR(Table4[[#This Row],[DZ-Score]]-C2,"-") -> 0.1392224 | E3: 8548728 | F3: =(Table4[[#This Row],[Rep.]]-'DR Breakdown'!$J$8)/'DR Breakdown'!$J$9 -> -1.4763659 | G3: =IFERROR(Table4[[#This Row],[RZ-Score]]-F2,"-") -> 0.2264384 | H3: 17675596 | I3: =(Table4[[#This Row],[Total]]-'DR Breakdown'!$M$8)/'DR Breakdown'!$M$9 -> -1.4567042
A4: 1920 | B4: 9139661 | C4: =(Table4[[#This Row],[Dem.]]-'DR Breakdown'!$G$8)/'DR Breakdown'!$G$9 -> -1.3799341 | D4: =IFERROR(Table4[[#This Row],[DZ-Score]]-C3,"-") -> 0.00062922428 | E4: 16144093 | F4: =(Table4[[#This Row],[Rep.]]-'DR Breakdown'!$J$8)/'DR Breakdown'!$J$9 -> -1.0877803 | G4: =IFERROR(Table4[[#This Row],[RZ-Score]]-F3,"-") -> 0.38858554 | H4: 25283754 | I4: =(Table4[[#This Row],[Total]]-'DR Breakdown'!$M$8)/'DR Breakdown'!$M$9 -> -1.262016
A5: 1924 | B5: 8386242 | C5: =(Table4[[#This Row],[Dem.]]-'DR Breakdown'!$G$8)/'DR Breakdown'!$G$9 -> -1.416991 | D5: =IFERROR(Table4[[#This Row],[DZ-Score]]-C4,"-") -> -0.037056947 | E5: 15723789 | F5: =(Table4[[#This Row],[Rep.]]-'DR Breakdown'!$J$8)/'DR Breakdown'!$J$9 -> -1.1092835 | G5: =IFERROR(Table4[[#This Row],[RZ-Score]]-F4,"-") -> -0.021503121 | H5: 24110031 | I5: =(Table4[[#This Row],[Total]]-'DR Breakdown'!$M$8)/'DR Breakdown'!$M$9 -> -1.2920509
A6: 1928 | B6: 15015464 | C6: =(Table4[[#This Row],[Dem.]]-'DR Breakdown'!$G$8)/'DR Breakdown'!$G$9 -> -1.0909325 | D6: =IFERROR(Table4[[#This Row],[DZ-Score]]-C5,"-") -> 0.32605858 | E6: 21427123 | F6: =(Table4[[#This Row],[Rep.]]-'DR Breakdown'!$J$8)/'DR Breakdown'!$J$9 -> -0.81749589 | G6: =IFERROR(Table4[[#This Row],[RZ-Score]]-F5,"-") -> 0.29178757 | H6: 36442587 | I6: =(Table4[[#This Row],[Total]]-'DR Breakdown'!$M$8)/'DR Breakdown'!$M$9 -> -0.97646821
A7: 1932 | B7: 22821277 | C7: =(Table4[[#This Row],[Dem.]]-'DR Breakdown'!$G$8)/'DR Breakdown'!$G$9 -> -0.7070032 | D7: =IFERROR(Table4[[#This Row],[DZ-Score]]-C6,"-") -> 0.38392926 | E7: 15761254 | F7: =(Table4[[#This Row],[Rep.]]-'DR Breakdown'!$J$8)/'DR Breakdown'!$J$9 -> -1.1073667 | G7: =IFERROR(Table4[[#This Row],[RZ-Score]]-F6,"-") -> -0.28987083 | H7: 38582531 | I7: =(Table4[[#This Row],[Total]]-'DR Breakdown'!$M$8)/'DR Breakdown'!$M$9 -> -0.92170834
A8: 1936 | B8: 27752648 | C8: =(Table4[[#This Row],[Dem.]]-'DR Breakdown'!$G$8)/'DR Breakdown'!$G$9 -> -0.4644535 | D8: =IFERROR(Table4[[#This Row],[DZ-Score]]-C7,"-") -> 0.2425497 | E8: 16681862 | F8: =(Table4[[#This Row],[Rep.]]-'DR Breakdown'!$J$8)/'DR Breakdown'!$J$9 -> -1.0602676 | G8: =IFERROR(Table4[[#This Row],[RZ-Score]]-F7,"-") -> 0.047099113 | H8: 44434510 | I8: =(Table4[[#This Row],[Total]]-'DR Breakdown'!$M$8)/'DR Breakdown'!$M$9 -> -0.77195971
A9: 1940 | B9: 27313945 | C9: =(Table4[[#This Row],[Dem.]]-'DR Breakdown'!$G$8)/'DR Breakdown'!$G$9 -> -0.48603113 | D9: =IFERROR(Table4[[#This Row],[DZ-Score]]-C8,"-") -> -0.021577627 | E9: 22347744 | F9: =(Table4[[#This Row],[Rep.]]-'DR Breakdown'!$J$8)/'DR Breakdown'!$J$9 -> -0.77039612 | G9: =IFERROR(Table4[[#This Row],[RZ-Score]]-F8,"-") -> 0.28987149 | H9: 49661689 | I9: =(Table4[[#This Row],[Total]]-'DR Breakdown'!$M$8)/'DR Breakdown'!$M$9 -> -0.63819935
A10: 1944 | B10: 25612916 | C10: =(Table4[[#This Row],[Dem.]]-'DR Breakdown'!$G$8)/'DR Breakdown'!$G$9 -> -0.56969631 | D10: =IFERROR(Table4[[#This Row],[DZ-Score]]-C9,"-") -> -0.083665187 | E10: 22017929 | F10: =(Table4[[#This Row],[Rep.]]-'DR Breakdown'!$J$8)/'DR Breakdown'!$J$9 -> -0.78726974 | G10: =IFERROR(Table4[[#This Row],[RZ-Score]]-F9,"-") -> -0.016873625 | H10: 47630845 | I10: =(Table4[[#This Row],[Total]]-'DR Breakdown'!$M$8)/'DR Breakdown'!$M$9 -> -0.69016743
A11: 1948 | B11: 24179347 | C11: =(Table4[[#This Row],[Dem.]]-'DR Breakdown'!$G$8)/'DR Breakdown'!$G$9 -> -0.64020647 | D11: =IFERROR(Table4[[#This Row],[DZ-Score]]-C10,"-") -> -0.070510155 | E11: 21991292 | F11: =(Table4[[#This Row],[Rep.]]-'DR Breakdown'!$J$8)/'DR Breakdown'!$J$9 -> -0.78863251 | G11: =IFERROR(Table4[[#This Row],[RZ-Score]]-F10,"-") -> -0.0013627723 | H11: 46170639 | I11: =(Table4[[#This Row],[Total]]-'DR Breakdown'!$M$8)/'DR Breakdown'!$M$9 -> -0.72753322
A12: 1952 | B12: 27375090 | C12: =(Table4[[#This Row],[Dem.]]-'DR Breakdown'!$G$8)/'DR Breakdown'!$G$9 -> -0.48302371 | D12: =IFERROR(Table4[[#This Row],[DZ-Score]]-C11,"-") -> 0.15718276 | E12: 34075529 | F12: =(Table4[[#This Row],[Rep.]]-'DR Breakdown'!$J$8)/'DR Breakdown'!$J$9 -> -0.17039234 | G12: =IFERROR(Table4[[#This Row],[RZ-Score]]-F11,"-") -> 0.61824017 | H12: 61450619 | I12: =(Table4[[#This Row],[Total]]-'DR Breakdown'!$M$8)/'DR Breakdown'!$M$9 -> -0.33652773
A13: 1956 | B13: 26028028 | C13: =(Table4[[#This Row],[Dem.]]-'DR Breakdown'!$G$8)/'DR Breakdown'!$G$9 -> -0.54927901 | D13: =IFERROR(Table4[[#This Row],[DZ-Score]]-C12,"-") -> -0.066255305 | E13: 35579180 | F13: =(Table4[[#This Row],[Rep.]]-'DR Breakdown'!$J$8)/'DR Breakdown'!$J$9 -> -0.09346424 | G13: =IFERROR(Table4[[#This Row],[RZ-Score]]-F12,"-") -> 0.076928104 | H13: 61607208 | I13: =(Table4[[#This Row],[Total]]-'DR Breakdown'!$M$8)/'DR Breakdown'!$M$9 -> -0.33252071
... A30: 2024 | B30: 71239855 | C30: =(Table4[[#This Row],[Dem.]]-'DR Breakdown'!$G$8)/'DR Breakdown'!$G$9 -> 1.6744667 | D30: =IFERROR(Table4[[#This Row],[DZ-Score]]-C29,"-") -> -0.49399718 | E30: 74834590 | F30: =(Table4[[#This Row],[Rep.]]-'DR Breakdown'!$J$8)/'DR Breakdown'!$J$9 -> 1.914877 | G30: =IFERROR(Table4[[#This Row],[RZ-Score]]-F29,"-") -> 0.031239599 | H30: 140459535 | I30: =(Table4[[#This Row],[Total]]-'DR Breakdown'!$M$8)/'DR Breakdown'!$M$9 -> 1.6852629

Sheet Votes and Population
A3: Year | B3: Population | C3: Dem Votes | D3: Rep Votes | E3: Total Votes | F3: T% of Pop | G3: Column3 | H3: T%Z-Score | I3: D% of Pop | J3: D%Z-Score2 | K3: Z Dif | L3: R% of Pop | M3: R% of Pop2 | N3: R%Z-Score | O3: RZ Dif
A4: 1912 | B4: =95330000/2 -> 47665000 | C4: 6296284 | D4: 4122721 | E4: =Table5[[#This Row],[Dem Votes]]+Table5[[#This Row],[Rep Votes]] -> 10419005 | F4: =Table5[[#This Row],[Total Votes]]/Table5[[#This Row],[Population]] -> 0.21858817 | G4: =IFERROR((Table5[[#This Row],[T% of Pop]]-F3)/F3,"-") -> - | H4: =(Table5[[#This Row],[T% of Pop]]-$R$17)/$R$18 -> -2.698839 | I4: =Table5[[#This Row],[Dem Votes]]/Table5[[#This Row],[Population]] -> 0.13209449 | J4: =(Table5[[#This Row],[D% of Pop]]-$Q$6)/$Q$7 -> -1.4267359 | K4: =IFERROR(Table5[[#This Row],[D%Z-Score2]]-J3,"-") -> - | L4: =Table5[[#This Row],[Rep Votes]]/Table5[[#This Row],[Population]] -> 0.086493675 | M4: =Table5[[#This Row],[Rep Votes]]/Table5[[#This Row],[Population]] -> 0.086493675 | N4: =(Table5[[#This Row],[R% of Pop2]]-$T$6)/$T$7 -> -2.3553886 | O4: =IFERROR(Table5[[#This Row],[R%Z-Score]]-N3,"-") -> -
A5: 1916 | B5: =101960000/1.5 -> 67973333 | C5: 9126868 | D5: 8548728 | E5: =Table5[[#This Row],[Dem Votes]]+Table5[[#This Row],[Rep Votes]] -> 17675596 | F5: =Table5[[#This Row],[Total Votes]]/Table5[[#This Row],[Population]] -> 0.26003721 | G5: =IFERROR((Table5[[#This Row],[T% of Pop]]-F4)/F4,"-") -> 0.18962162 | H5: =(Table5[[#This Row],[T% of Pop]]-$R$17)/$R$18 -> -1.9113571 | I5: =Table5[[#This Row],[Dem Votes]]/Table5[[#This Row],[Population]] -> 0.1342713 | J5: =(Table5[[#This Row],[D% of Pop]]-$Q$6)/$Q$7 -> -1.3592776 | K5: =IFERROR(Table5[[#This Row],[D%Z-Score2]]-J4,"-") -> 0.067458295 | L5: =Table5[[#This Row],[Rep Votes]]/Table5[[#This Row],[Population]] -> 0.12576591 | M5: =Table5[[#This Row],[Rep Votes]]/Table5[[#This Row],[Population]] -> 0.12576591 | N5: =(Table5[[#This Row],[R% of Pop2]]-$T$6)/$T$7 -> -1.3919718 | O5: =IFERROR(Table5[[#This Row],[R%Z-Score]]-N4,"-") -> 0.96341677 | P5: D | S5: R
A6: 1920 | B6: =106460000/1.5 -> 70973333 | C6: 9139661 | D6: 16144093 | E6: =Table5[[#This Row],[Dem Votes]]+Table5[[#This Row],[Rep Votes]] -> 25283754 | F6: =Table5[[#This Row],[Total Votes]]/Table5[[#This Row],[Population]] -> 0.35624301 | G6: =IFERROR((Table5[[#This Row],[T% of Pop]]-F5)/F5,"-") -> 0.36996936 | H6: =(Table5[[#This Row],[T% of Pop]]-$R$17)/$R$18 -> -0.083562794 | I6: =Table5[[#This Row],[Dem Votes]]/Table5[[#This Row],[Population]] -> 0.12877599 | J6: =(Table5[[#This Row],[D% of Pop]]-$Q$6)/$Q$7 -> -1.5295748 | K6: =IFERROR(Table5[[#This Row],[D%Z-Score2]]-J5,"-") -> -0.17029723 | L6: =Table5[[#This Row],[Rep Votes]]/Table5[[#This Row],[Population]] -> 0.22746703 | M6: =Table5[[#This Row],[Rep Votes]]/Table5[[#This Row],[Population]] -> 0.22746703 | N6: =(Table5[[#This Row],[R% of Pop2]]-$T$6)/$T$7 -> 1.102935 | O6: =IFERROR(Table5[[#This Row],[R%Z-Score]]-N5,"-") -> 2.4949068 | P6: Mean | Q6: =AVERAGE(Table5[D% of Pop]) -> 0.17813379 | S6: Mean | T6: =AVERAGE(Table5[R% of Pop]) -> 0.18250754
A7: 1924 | B7: =114110000/2 -> 57055000 | C7: 8386242 | D7: 15723789 | E7: =Table5[[#This Row],[Dem Votes]]+Table5[[#This Row],[Rep Votes]] -> 24110031 | F7: =Table5[[#This Row],[Total Votes]]/Table5[[#This Row],[Population]] -> 0.42257525 | G7: =IFERROR((Table5[[#This Row],[T% of Pop]]-F6)/F6,"-") -> 0.18619942 | H7: =(Table5[[#This Row],[T% of Pop]]-$R$17)/$R$18 -> 1.1766699 | I7: =Table5[[#This Row],[Dem Votes]]/Table5[[#This Row],[Population]] -> 0.14698522 | J7: =(Table5[[#This Row],[D% of Pop]]-$Q$6)/$Q$7 -> -0.96527922 | K7: =IFERROR(Table5[[#This Row],[D%Z-Score2]]-J6,"-") -> 0.56429563 | L7: =Table5[[#This Row],[Rep Votes]]/Table5[[#This Row],[Population]] -> 0.27559003 | M7: =Table5[[#This Row],[Rep Votes]]/Table5[[#This Row],[Population]] -> 0.27559003 | N7: =(Table5[[#This Row],[R% of Pop2]]-$T$6)/$T$7 -> 2.2834766 | O7: =IFERROR(Table5[[#This Row],[R%Z-Score]]-N6,"-") -> 1.1805416 | P7: SD | Q7: =_xlfn.STDEV.S(Table5[D% of Pop]) -> 0.03226897 | S7: SD | T7: =_xlfn.STDEV.S(Table5[R% of Pop]) -> 0.040763494
A8: 1928 | B8: =120510000 -> 120510000 | C8: 15015464 | D8: 21427123 | E8: =Table5[[#This Row],[Dem Votes]]+Table5[[#This Row],[Rep Votes]] -> 36442587 | F8: =Table5[[#This Row],[Total Votes]]/Table5[[#This Row],[Population]] -> 0.30240301 | G8: =IFERROR((Table5[[#This Row],[T% of Pop]]-F7)/F7,"-") -> -0.28438069 | H8: =(Table5[[#This Row],[T% of Pop]]-$R$17)/$R$18 -> -1.1064579 | I8: =Table5[[#This Row],[Dem Votes]]/Table5[[#This Row],[Population]] -> 0.12459932 | J8: =(Table5[[#This Row],[D% of Pop]]-$Q$6)/$Q$7 -> -1.6590078 | K8: =IFERROR(Table5[[#This Row],[D%Z-Score2]]-J7,"-") -> -0.69372854 | L8: =Table5[[#This Row],[Rep Votes]]/Table5[[#This Row],[Population]] -> 0.17780369 | M8: =Table5[[#This Row],[Rep Votes]]/Table5[[#This Row],[Population]] -> 0.17780369 | N8: =(Table5[[#This Row],[R% of Pop2]]-$T$6)/$T$7 -> -0.11539367 | O8: =IFERROR(Table5[[#This Row],[R%Z-Score]]-N7,"-") -> -2.3988703 | P8: Q1 | Q8: =_xlfn.QUARTILE.INC(Table5[D% of Pop],1) -> 0.15580608 | S8: Q1 | T8: =_xlfn.QUARTILE.INC(Table5[R% of Pop],1) -> 0.15244844
A9: 1932 | B9: 124840000 | C9: 22821277 | D9: 15761254 | E9: =Table5[[#This Row],[Dem Votes]]+Table5[[#This Row],[Rep Votes]] -> 38582531 | F9: =Table5[[#This Row],[Total Votes]]/Table5[[#This Row],[Population]] -> 0.30905584 | G9: =IFERROR((Table5[[#This Row],[T% of Pop]]-F8)/F8,"-") -> 0.021999871 | H9: =(Table5[[#This Row],[T% of Pop]]-$R$17)/$R$18 -> -0.98006223 | I9: =Table5[[#This Row],[Dem Votes]]/Table5[[#This Row],[Population]] -> 0.18280421 | J9: =(Table5[[#This Row],[D% of Pop]]-$Q$6)/$Q$7 -> 0.14473393 | K9: =IFERROR(Table5[[#This Row],[D%Z-Score2]]-J8,"-") -> 1.8037417 | L9: =Table5[[#This Row],[Rep Votes]]/Table5[[#This Row],[Population]] -> 0.12625163 | M9: =Table5[[#This Row],[Rep Votes]]/Table5[[#This Row],[Population]] -> 0.12625163 | N9: =(Table5[[#This Row],[R% of Pop2]]-$T$6)/$T$7 -> -1.3800561 | O9: =IFERROR(Table5[[#This Row],[R%Z-Score]]-N8,"-") -> -1.2646624 | P9: Q3 | Q9: =_xlfn.QUARTILE.INC(Table5[D% of Pop],3) -> 0.20391873 | S9: Q3 | T9: =_xlfn.QUARTILE.INC(Table5[R% of Pop],3) -> 0.21188009
A10: 1936 | B10: 1.2805e+08 | C10: 27752648 | D10: 16681862 | E10: =Table5[[#This Row],[Dem Votes]]+Table5[[#This Row],[Rep Votes]] -> 44434510 | F10: =Table5[[#This Row],[Total Votes]]/Table5[[#This Row],[Population]] -> 0.34700906 | G10: =IFERROR((Table5[[#This Row],[T% of Pop]]-F9)/F9,"-") -> 0.12280376 | H10: =(Table5[[#This Row],[T% of Pop]]-$R$17)/$R$18 -> -0.25899677 | I10: =Table5[[#This Row],[Dem Votes]]/Table5[[#This Row],[Population]] -> 0.2167329 | J10: =(Table5[[#This Row],[D% of Pop]]-$Q$6)/$Q$7 -> 1.1961681 | K10: =IFERROR(Table5[[#This Row],[D%Z-Score2]]-J9,"-") -> 1.0514341 | L10: =Table5[[#This Row],[Rep Votes]]/Table5[[#This Row],[Population]] -> 0.13027616 | M10: =Table5[[#This Row],[Rep Votes]]/Table5[[#This Row],[Population]] -> 0.13027616 | N10: =(Table5[[#This Row],[R% of Pop2]]-$T$6)/$T$7 -> -1.2813275 | O10: =IFERROR(Table5[[#This Row],[R%Z-Score]]-N9,"-") -> 0.098728624 | P10: IQR | Q10: =Q9-Q8 -> 0.048112645 | S10: IQR | T10: =T9-T8 -> 0.05943165
A11: 1940 | B11: 132120000 | C11: 27313945 | D11: 22347744 | E11: =Table5[[#This Row],[Dem Votes]]+Table5[[#This Row],[Rep Votes]] -> 49661689 | F11: =Table5[[#This Row],[Total Votes]]/Table5[[#This Row],[Population]] -> 0.3758832 | G11: =IFERROR((Table5[[#This Row],[T% of Pop]]-F10)/F10,"-") -> 0.083208622 | H11: =(Table5[[#This Row],[T% of Pop]]-$R$17)/$R$18 -> 0.28957722 | I11: =Table5[[#This Row],[Dem Votes]]/Table5[[#This Row],[Population]] -> 0.20673588 | J11: =(Table5[[#This Row],[D% of Pop]]-$Q$6)/$Q$7 -> 0.88636526 | K11: =IFERROR(Table5[[#This Row],[D%Z-Score2]]-J10,"-") -> -0.3098028 | L11: =Table5[[#This Row],[Rep Votes]]/Table5[[#This Row],[Population]] -> 0.16914732 | M11: =Table5[[#This Row],[Rep Votes]]/Table5[[#This Row],[Population]] -> 0.16914732 | N11: =(Table5[[#This Row],[R% of Pop2]]-$T$6)/$T$7 -> -0.32774965 | O11: =IFERROR(Table5[[#This Row],[R%Z-Score]]-N10,"-") -> 0.9535778 | P11: UF | Q11: =Q9+(1.5*Q10) -> 0.27608769 | S11: UF | T11: =T9+(1.5*T10) -> 0.30102757
A12: 1944 | B12: 138400000 | C12: 25612916 | D12: 22017929 | E12: =Table5[[#This Row],[Dem Votes]]+Table5[[#This Row],[Rep Votes]] -> 47630845 | F12: =Table5[[#This Row],[Total Votes]]/Table5[[#This Row],[Population]] -> 0.3441535 | G12: =IFERROR((Table5[[#This Row],[T% of Pop]]-F11)/F11,"-") -> -0.084413722 | H12: =(Table5[[#This Row],[T% of Pop]]-$R$17)/$R$18 -> -0.31324887 | I12: =Table5[[#This Row],[Dem Votes]]/Table5[[#This Row],[Population]] -> 0.18506442 | J12: =(Table5[[#This Row],[D% of Pop]]-$Q$6)/$Q$7 -> 0.21477697 | K12: =IFERROR(Table5[[#This Row],[D%Z-Score2]]-J11,"-") -> -0.67158829 | L12: =Table5[[#This Row],[Rep Votes]]/Table5[[#This Row],[Population]] -> 0.15908908 | M12: =Table5[[#This Row],[Rep Votes]]/Table5[[#This Row],[Population]] -> 0.15908908 | N12: =(Table5[[#This Row],[R% of Pop2]]-$T$6)/$T$7 -> -0.57449588 | O12: =IFERROR(Table5[[#This Row],[R%Z-Score]]-N11,"-") -> -0.24674623 | P12: Min | Q12: =MIN(Table5[D% of Pop]) -> 0.12459932 | S12: Min | T12: =MIN(Table5[R% of Pop]) -> 0.086493675
A13: 1948 | B13: 146630000 | C13: 24179347 | D13: 21991292 | E13: =Table5[[#This Row],[Dem Votes]]+Table5[[#This Row],[Rep Votes]] -> 46170639 | F13: =Table5[[#This Row],[Total Votes]]/Table5[[#This Row],[Population]] -> 0.31487853 | G13: =IFERROR((Table5[[#This Row],[T% of Pop]]-F12)/F12,"-") -> -0.085063708 | H13: =(Table5[[#This Row],[T% of Pop]]-$R$17)/$R$18 -> -0.8694381 | I13: =Table5[[#This Row],[Dem Votes]]/Table5[[#This Row],[Population]] -> 0.16490041 | J13: =(Table5[[#This Row],[D% of Pop]]-$Q$6)/$Q$7 -> -0.41009618 | K13: =IFERROR(Table5[[#This Row],[D%Z-Score2]]-J12,"-") -> -0.62487315 | L13: =Table5[[#This Row],[Rep Votes]]/Table5[[#This Row],[Population]] -> 0.14997812 | M13: =Table5[[#This Row],[Rep Votes]]/Table5[[#This Row],[Population]] -> 0.14997812 | N13: =(Table5[[#This Row],[R% of Pop2]]-$T$6)/$T$7 -> -0.79800372 | O13: =IFERROR(Table5[[#This Row],[R%Z-Score]]-N12,"-") -> -0.22350784 | P13: Max | Q13: =MAX(Table5[D% of Pop]) -> 0.24517691 | S13: Max | T13: =MAX(Table5[R% of Pop]) -> 0.27559003
A14: 1952 | B14: 157550000 | C14: 27375090 | D14: 34075529 | E14: =Table5[[#This Row],[Dem Votes]]+Table5[[#This Row],[Rep Votes]] -> 61450619 | F14: =Table5[[#This Row],[Total Votes]]/Table5[[#This Row],[Population]] -> 0.39003884 | G14: =IFERROR((Table5[[#This Row],[T% of Pop]]-F13)/F13,"-") -> 0.2386962 | H14: =(Table5[[#This Row],[T% of Pop]]-$R$17)/$R$18 -> 0.55851721 | I14: =Table5[[#This Row],[Dem Votes]]/Table5[[#This Row],[Population]] -> 0.17375493 | J14: =(Table5[[#This Row],[D% of Pop]]-$Q$6)/$Q$7 -> -0.13569865 | K14: =IFERROR(Table5[[#This Row],[D%Z-Score2]]-J13,"-") -> 0.27439754 | L14: =Table5[[#This Row],[Rep Votes]]/Table5[[#This Row],[Population]] -> 0.2162839 | M14: =Table5[[#This Row],[Rep Votes]]/Table5[[#This Row],[Population]] -> 0.2162839 | N14: =(Table5[[#This Row],[R% of Pop2]]-$T$6)/$T$7 -> 0.8285934 | O14: =IFERROR(Table5[[#This Row],[R%Z-Score]]-N13,"-") -> 1.6265971
A15: 1956 | B15: 168900000 | C15: 26028028 | D15: 35579180 | E15: =Table5[[#This Row],[Dem Votes]]+Table5[[#This Row],[Rep Votes]] -> 61607208 | F15: =Table5[[#This Row],[Total Votes]]/Table5[[#This Row],[Population]] -> 0.36475552 | G15: =IFERROR((Table5[[#This Row],[T% of Pop]]-F14)/F14,"-") -> -0.064822556 | H15: =(Table5[[#This Row],[T% of Pop]]-$R$17)/$R$18 -> 0.078164691 | I15: =Table5[[#This Row],[Dem Votes]]/Table5[[#This Row],[Population]] -> 0.15410319 | J15: =(Table5[[#This Row],[D% of Pop]]-$Q$6)/$Q$7 -> -0.74469701 | K15: =IFERROR(Table5[[#This Row],[D%Z-Score2]]-J14,"-") -> -0.60899836 | L15: =Table5[[#This Row],[Rep Votes]]/Table5[[#This Row],[Population]] -> 0.21065234 | M15: =Table5[[#This Row],[Rep Votes]]/Table5[[#This Row],[Population]] -> 0.21065234 | N15: =(Table5[[#This Row],[R% of Pop2]]-$T$6)/$T$7 -> 0.69044124 | O15: =IFERROR(Table5[[#This Row],[R%Z-Score]]-N14,"-") -> -0.13815216
A16: 1960 | B16: 180670000 | C16: 34220984 | D16: 34108157 | E16: =Table5[[#This Row],[Dem Votes]]+Table5[[#This Row],[Rep Votes]] -> 68329141 | F16: =Table5[[#This Row],[Total Votes]]/Table5[[#This Row],[Population]] -> 0.3781986 | G16: =IFERROR((Table5[[#This Row],[T% of Pop]]-F15)/F15,"-") -> 0.03685503 | H16: =(Table5[[#This Row],[T% of Pop]]-$R$17)/$R$18 -> 0.33356694 | I16: =Table5[[#This Row],[Dem Votes]]/Table5[[#This Row],[Population]] -> 0.18941155 | J16: =(Table5[[#This Row],[D% of Pop]]-$Q$6)/$Q$7 -> 0.34949227 | K16: =IFERROR(Table5[[#This Row],[D%Z-Score2]]-J15,"-") -> 1.0941893 | L16: =Table5[[#This Row],[Rep Votes]]/Table5[[#This Row],[Population]] -> 0.18878705 | M16: =Table5[[#This Row],[Rep Votes]]/Table5[[#This Row],[Population]] -> 0.18878705 | N16: =(Table5[[#This Row],[R% of Pop2]]-$T$6)/$T$7 -> 0.15404745 | O16: =IFERROR(Table5[[#This Row],[R%Z-Score]]-N15,"-") -> -0.53639379 | T16: P(x<a) | U16: P(x>a)
A17: 1964 | B17: 191890000 | C17: 43129040 | D17: 27175754 | E17: =Table5[[#This Row],[Dem Votes]]+Table5[[#This Row],[Rep Votes]] -> 70304794 | F17: =Table5[[#This Row],[Total Votes]]/Table5[[#This Row],[Population]] -> 0.36638071 | G17: =IFERROR((Table5[[#This Row],[T% of Pop]]-F16)/F16,"-") -> -0.031247847 | H17: =(Table5[[#This Row],[T% of Pop]]-$R$17)/$R$18 -> 0.10904122 | I17: =Table5[[#This Row],[Dem Votes]]/Table5[[#This Row],[Population]] -> 0.22475918 | J17: =(Table5[[#This Row],[D% of Pop]]-$Q$6)/$Q$7 -> 1.4448988 | K17: =IFERROR(Table5[[#This Row],[D%Z-Score2]]-J16,"-") -> 1.0954065 | L17: =Table5[[#This Row],[Rep Votes]]/Table5[[#This Row],[Population]] -> 0.14162152 | M17: =Table5[[#This Row],[Rep Votes]]/Table5[[#This Row],[Population]] -> 0.14162152 | N17: =(Table5[[#This Row],[R% of Pop2]]-$T$6)/$T$7 -> -1.0030058 | O17: =IFERROR(Table5[[#This Row],[R%Z-Score]]-N16,"-") -> -1.1570532 | Q17: Mean | R17: =AVERAGE(Table5[T% of Pop]) -> 0.36064133 | T17: =_xlfn.NORM.DIST(R25,R17,R18,TRUE) -> 0.94550099 | U17: =1-T17 -> 0.054499006
A18: 1968 | B18: 200710000 | C18: 31271839 | D18: 31783783 | E18: =Table5[[#This Row],[Dem Votes]]+Table5[[#This Row],[Rep Votes]] -> 63055622 | F18: =Table5[[#This Row],[Total Votes]]/Table5[[#This Row],[Population]] -> 0.31416283 | G18: =IFERROR((Table5[[#This Row],[T% of Pop]]-F17)/F17,"-") -> -0.14252354 | H18: =(Table5[[#This Row],[T% of Pop]]-$R$17)/$R$18 -> -0.88303552 | I18: =Table5[[#This Row],[Dem Votes]]/Table5[[#This Row],[Population]] -> 0.15580608 | J18: =(Table5[[#This Row],[D% of Pop]]-$Q$6)/$Q$7 -> -0.69192501 | K18: =IFERROR(Table5[[#This Row],[D%Z-Score2]]-J17,"-") -> -2.1368238 | L18: =Table5[[#This Row],[Rep Votes]]/Table5[[#This Row],[Population]] -> 0.15835675 | M18: =Table5[[#This Row],[Rep Votes]]/Table5[[#This Row],[Population]] -> 0.15835675 | N18: =(Table5[[#This Row],[R% of Pop2]]-$T$6)/$T$7 -> -0.59246131 | O18: =IFERROR(Table5[[#This Row],[R%Z-Score]]-N17,"-") -> 0.41054444 | Q18: SD | R18: =_xlfn.STDEV.S(Table5[T% of Pop]) -> 0.052634916
A19: 1972 | B19: 209900000 | C19: 29173222 | D19: 47168710 | E19: =Table5[[#This Row],[Dem Votes]]+Table5[[#This Row],[Rep Votes]] -> 76341932 | F19: =Table5[[#This Row],[Total Votes]]/Table5[[#This Row],[Population]] -> 0.3637062 | G19: =IFERROR((Table5[[#This Row],[T% of Pop]]-F18)/F18,"-") -> 0.15769966 | H19: =(Table5[[#This Row],[T% of Pop]]-$R$17)/$R$18 -> 0.058228856 | I19: =Table5[[#This Row],[Dem Votes]]/Table5[[#This Row],[Population]] -> 0.13898629 | J19: =(Table5[[#This Row],[D% of Pop]]-$Q$6)/$Q$7 -> -1.2131624 | K19: =IFERROR(Table5[[#This Row],[D%Z-Score2]]-J18,"-") -> -0.52123743 | L19: =Table5[[#This Row],[Rep Votes]]/Table5[[#This Row],[Population]] -> 0.22471991 | M19: =Table5[[#This Row],[Rep Votes]]/Table5[[#This Row],[Population]] -> 0.22471991 | N19: =(Table5[[#This Row],[R% of Pop2]]-$T$6)/$T$7 -> 1.0355435 | O19: =IFERROR(Table5[[#This Row],[R%Z-Score]]-N18,"-") -> 1.6280049 | Q19: Q1 | R19: =_xlfn.QUARTILE.INC(Table5[T% of Pop],1) -> 0.3275289
A20: 1976 | B20: 218040000 | C20: 40831881 | D20: 39148634 | E20: =Table5[[#This Row],[Dem Votes]]+Table5[[#This Row],[Rep Votes]] -> 79980515 | F20: =Table5[[#This Row],[Total Votes]]/Table5[[#This Row],[Population]] -> 0.36681579 | G20: =IFERROR((Table5[[#This Row],[T% of Pop]]-F19)/F19,"-") -> 0.0085497242 | H20: =(Table5[[#This Row],[T% of Pop]]-$R$17)/$R$18 -> 0.11730728 | I20: =Table5[[#This Row],[Dem Votes]]/Table5[[#This Row],[Population]] -> 0.18726785 | J20: =(Table5[[#This Row],[D% of Pop]]-$Q$6)/$Q$7 -> 0.28306001 | K20: =IFERROR(Table5[[#This Row],[D%Z-Score2]]-J19,"-") -> 1.4962224 | L20: =Table5[[#This Row],[Rep Votes]]/Table5[[#This Row],[Population]] -> 0.17954795 | M20: =Table5[[#This Row],[Rep Votes]]/Table5[[#This Row],[Population]] -> 0.17954795 | N20: =(Table5[[#This Row],[R% of Pop2]]-$T$6)/$T$7 -> -0.072604087 | O20: =IFERROR(Table5[[#This Row],[R%Z-Score]]-N19,"-") -> -1.1081476 | Q20: Q3 | R20: =_xlfn.QUARTILE.INC(Table5[T% of Pop],3) -> 0.39026725
A21: 1980 | B21: 227220000 | C21: 35481115 | D21: 43903230 | E21: =Table5[[#This Row],[Dem Votes]]+Table5[[#This Row],[Rep Votes]] -> 79384345 | F21: =Table5[[#This Row],[Total Votes]]/Table5[[#This Row],[Population]] -> 0.34937217 | G21: =IFERROR((Table5[[#This Row],[T% of Pop]]-F20)/F20,"-") -> -0.047554164 | H21: =(Table5[[#This Row],[T% of Pop]]-$R$17)/$R$18 -> -0.21410046 | I21: =Table5[[#This Row],[Dem Votes]]/Table5[[#This Row],[Population]] -> 0.15615313 | J21: =(Table5[[#This Row],[D% of Pop]]-$Q$6)/$Q$7 -> -0.68117009 | K21: =IFERROR(Table5[[#This Row],[D%Z-Score2]]-J20,"-") -> -0.9642301 | L21: =Table5[[#This Row],[Rep Votes]]/Table5[[#This Row],[Population]] -> 0.19321904 | M21: =Table5[[#This Row],[Rep Votes]]/Table5[[#This Row],[Population]] -> 0.19321904 | N21: =(Table5[[#This Row],[R% of Pop2]]-$T$6)/$T$7 -> 0.26277181 | O21: =IFERROR(Table5[[#This Row],[R%Z-Score]]-N20,"-") -> 0.3353759 | Q21: IQR | R21: =R20-R19 -> 0.062738351
A22: 1984 | B22: 235820000 | C22: 37577352 | D22: 54455472 | E22: =Table5[[#This Row],[Dem Votes]]+Table5[[#This Row],[Rep Votes]] -> 92032824 | F22: =Table5[[#This Row],[Total Votes]]/Table5[[#This Row],[Population]] -> 0.39026725 | G22: =IFERROR((Table5[[#This Row],[T% of Pop]]-F21)/F21,"-") -> 0.11705306 | H22: =(Table5[[#This Row],[T% of Pop]]-$R$17)/$R$18 -> 0.56285685 | I22: =Table5[[#This Row],[Dem Votes]]/Table5[[#This Row],[Population]] -> 0.1593476 | J22: =(Table5[[#This Row],[D% of Pop]]-$Q$6)/$Q$7 -> -0.58217497 | K22: =IFERROR(Table5[[#This Row],[D%Z-Score2]]-J21,"-") -> 0.098995122 | L22: =Table5[[#This Row],[Rep Votes]]/Table5[[#This Row],[Population]] -> 0.23091965 | M22: =Table5[[#This Row],[Rep Votes]]/Table5[[#This Row],[Population]] -> 0.23091965 | N22: =(Table5[[#This Row],[R% of Pop2]]-$T$6)/$T$7 -> 1.1876339 | O22: =IFERROR(Table5[[#This Row],[R%Z-Score]]-N21,"-") -> 0.92486213 | Q22: UF | R22: =R20+(1.5*R21) -> 0.48437478
A23: 1988 | B23: 244500000 | C23: 41809476 | D23: 48886597 | E23: =Table5[[#This Row],[Dem Votes]]+Table5[[#This Row],[Rep Votes]] -> 90696073 | F23: =Table5[[#This Row],[Total Votes]]/Table5[[#This Row],[Population]] -> 0.37094508 | G23: =IFERROR((Table5[[#This Row],[T% of Pop]]-F22)/F22,"-") -> -0.0495101 | H23: =(Table5[[#This Row],[T% of Pop]]-$R$17)/$R$18 -> 0.19575887 | I23: =Table5[[#This Row],[Dem Votes]]/Table5[[#This Row],[Population]] -> 0.1709999 | J23: =(Table5[[#This Row],[D% of Pop]]-$Q$6)/$Q$7 -> -0.22107581 | K23: =IFERROR(Table5[[#This Row],[D%Z-Score2]]-J22,"-") -> 0.36109916 | L23: =Table5[[#This Row],[Rep Votes]]/Table5[[#This Row],[Population]] -> 0.19994518 | M23: =Table5[[#This Row],[Rep Votes]]/Table5[[#This Row],[Population]] -> 0.19994518 | N23: =(Table5[[#This Row],[R% of Pop2]]-$T$6)/$T$7 -> 0.4277759 | O23: =IFERROR(Table5[[#This Row],[R%Z-Score]]-N22,"-") -> -0.75985804 | Q23: Min | R23: =MIN(Table5[T% of Pop]) -> 0.21858817
A24: 1992 | B24: 256510000 | C24: 44909889 | D24: 39104550 | E24: =Table5[[#This Row],[Dem Votes]]+Table5[[#This Row],[Rep Votes]] -> 84014439 | F24: =Table5[[#This Row],[Total Votes]]/Table5[[#This Row],[Population]] -> 0.3275289 | G24: =IFERROR((Table5[[#This Row],[T% of Pop]]-F23)/F23,"-") -> -0.11704207 | H24: =(Table5[[#This Row],[T% of Pop]]-$R$17)/$R$18 -> -0.62909626 | I24: =Table5[[#This Row],[Dem Votes]]/Table5[[#This Row],[Population]] -> 0.17508046 | J24: =(Table5[[#This Row],[D% of Pop]]-$Q$6)/$Q$7 -> -0.094621232 | K24: =IFERROR(Table5[[#This Row],[D%Z-Score2]]-J23,"-") -> 0.12645458 | L24: =Table5[[#This Row],[Rep Votes]]/Table5[[#This Row],[Population]] -> 0.15244844 | M24: =Table5[[#This Row],[Rep Votes]]/Table5[[#This Row],[Population]] -> 0.15244844 | N24: =(Table5[[#This Row],[R% of Pop2]]-$T$6)/$T$7 -> -0.73740242 | O24: =IFERROR(Table5[[#This Row],[R%Z-Score]]-N23,"-") -> -1.1651783 | Q24: Max | R24: =MAX(Table5[T% of Pop]) -> 0.46906004
A25: 1996 | B25: 269390000 | C25: 47401185 | D25: 39197469 | E25: =Table5[[#This Row],[Dem Votes]]+Table5[[#This Row],[Rep Votes]] -> 86598654 | F25: =Table5[[#This Row],[Total Votes]]/Table5[[#This Row],[Population]] -> 0.32146202 | G25: =IFERROR((Table5[[#This Row],[T% of Pop]]-F24)/F24,"-") -> -0.018523195 | H25: =(Table5[[#This Row],[T% of Pop]]-$R$17)/$R$18 -> -0.74435971 | I25: =Table5[[#This Row],[Dem Votes]]/Table5[[#This Row],[Population]] -> 0.17595748 | J25: =(Table5[[#This Row],[D% of Pop]]-$Q$6)/$Q$7 -> -0.067442887 | K25: =IFERROR(Table5[[#This Row],[D%Z-Score2]]-J24,"-") -> 0.027178346 | L25: =Table5[[#This Row],[Rep Votes]]/Table5[[#This Row],[Population]] -> 0.14550454 | M25: =Table5[[#This Row],[Rep Votes]]/Table5[[#This Row],[Population]] -> 0.14550454 | N25: =(Table5[[#This Row],[R% of Pop2]]-$T$6)/$T$7 -> -0.90774844 | O25: =IFERROR(Table5[[#This Row],[R%Z-Score]]-N24,"-") -> -0.17034602 | Q25: a | R25: 0.445
A26: 2000 | B26: 282160000 | C26: 50999897 | D26: 50456002 | E26: =Table5[[#This Row],[Dem Votes]]+Table5[[#This Row],[Rep Votes]] -> 101455899 | F26: =Table5[[#This Row],[Total Votes]]/Table5[[#This Row],[Population]] -> 0.35956868 | G26: =IFERROR((Table5[[#This Row],[T% of Pop]]-F25)/F25,"-") -> 0.11854171 | H26: =(Table5[[#This Row],[T% of Pop]]-$R$17)/$R$18 -> -0.02037908 | I26: =Table5[[#This Row],[Dem Votes]]/Table5[[#This Row],[Population]] -> 0.18074815 | J26: =(Table5[[#This Row],[D% of Pop]]-$Q$6)/$Q$7 -> 0.081017647 | K26: =IFERROR(Table5[[#This Row],[D%Z-Score2]]-J25,"-") -> 0.14846053 | L26: =Table5[[#This Row],[Rep Votes]]/Table5[[#This Row],[Population]] -> 0.17882053 | M26: =Table5[[#This Row],[Rep Votes]]/Table5[[#This Row],[Population]] -> 0.17882053 | N26: =(Table5[[#This Row],[R% of Pop2]]-$T$6)/$T$7 -> -0.090448752 | O26: =IFERROR(Table5[[#This Row],[R%Z-Score]]-N25,"-") -> 0.81729969
A27: 2004 | B27: 292810000 | C27: 59028444 | D27: 62040610 | E27: =Table5[[#This Row],[Dem Votes]]+Table5[[#This Row],[Rep Votes]] -> 121069054 | F27: =Table5[[#This Row],[Total Votes]]/Table5[[#This Row],[Population]] -> 0.41347308 | G27: =IFERROR((Table5[[#This Row],[T% of Pop]]-F26)/F26,"-") -> 0.14991407 | H27: =(Table5[[#This Row],[T% of Pop]]-$R$17)/$R$18 -> 1.0037397 | I27: =Table5[[#This Row],[Dem Votes]]/Table5[[#This Row],[Population]] -> 0.20159299 | J27: =(Table5[[#This Row],[D% of Pop]]-$Q$6)/$Q$7 -> 0.72698948 | K27: =IFERROR(Table5[[#This Row],[D%Z-Score2]]-J26,"-") -> 0.64597184 | L27: =Table5[[#This Row],[Rep Votes]]/Table5[[#This Row],[Population]] -> 0.21188009 | M27: =Table5[[#This Row],[Rep Votes]]/Table5[[#This Row],[Population]] -> 0.21188009 | N27: =(Table5[[#This Row],[R% of Pop2]]-$T$6)/$T$7 -> 0.7205602 | O27: =IFERROR(Table5[[#This Row],[R%Z-Score]]-N26,"-") -> 0.81100895
A28: 2008 | B28: 304090000 | C28: 69498516 | D28: 59948323 | E28: =Table5[[#This Row],[Dem Votes]]+Table5[[#This Row],[Rep Votes]] -> 129446839 | F28: =Table5[[#This Row],[Total Votes]]/Table5[[#This Row],[Population]] -> 0.42568594 | G28: =IFERROR((Table5[[#This Row],[T% of Pop]]-F27)/F27,"-") -> 0.029537255 | H28: =(Table5[[#This Row],[T% of Pop]]-$R$17)/$R$18 -> 1.2357693 | I28: =Table5[[#This Row],[Dem Votes]]/Table5[[#This Row],[Population]] -> 0.22854588 | J28: =(Table5[[#This Row],[D% of Pop]]-$Q$6)/$Q$7 -> 1.5622466 | K28: =IFERROR(Table5[[#This Row],[D%Z-Score2]]-J27,"-") -> 0.8352571 | L28: =Table5[[#This Row],[Rep Votes]]/Table5[[#This Row],[Population]] -> 0.19714007 | M28: =Table5[[#This Row],[Rep Votes]]/Table5[[#This Row],[Population]] -> 0.19714007 | N28: =(Table5[[#This Row],[R% of Pop2]]-$T$6)/$T$7 -> 0.35896152 | O28: =IFERROR(Table5[[#This Row],[R%Z-Score]]-N27,"-") -> -0.36159869 | Q28: =AVERAGE(Table5[Column3]) -> 0.033620907
A29: 2012 | B29: 313830000 | C29: 65915795 | D29: 60933504 | E29: =Table5[[#This Row],[Dem Votes]]+Table5[[#This Row],[Rep Votes]] -> 126849299 | F29: =Table5[[#This Row],[Total Votes]]/Table5[[#This Row],[Population]] -> 0.40419749 | G29: =IFERROR((Table5[[#This Row],[T% of Pop]]-F28)/F28,"-") -> -0.050479592 | H29: =(Table5[[#This Row],[T% of Pop]]-$R$17)/$R$18 -> 0.82751458 | I29: =Table5[[#This Row],[Dem Votes]]/Table5[[#This Row],[Population]] -> 0.21003663 | J29: =(Table5[[#This Row],[D% of Pop]]-$Q$6)/$Q$7 -> 0.98865375 | K29: =IFERROR(Table5[[#This Row],[D%Z-Score2]]-J28,"-") -> -0.57359284 | L29: =Table5[[#This Row],[Rep Votes]]/Table5[[#This Row],[Population]] -> 0.19416086 | M29: =Table5[[#This Row],[Rep Votes]]/Table5[[#This Row],[Population]] -> 0.19416086 | N29: =(Table5[[#This Row],[R% of Pop2]]-$T$6)/$T$7 -> 0.28587644 | O29: =IFERROR(Table5[[#This Row],[R%Z-Score]]-N28,"-") -> -0.073085073 | Q29: =_xlfn.STDEV.S(Table5[Column3]) -> 0.13765753 | R29: =Q29*2 -> 0.27531506
A30: 2016 | B30: 322940000 | C30: 65853514 | D30: 62984828 | E30: =Table5[[#This Row],[Dem Votes]]+Table5[[#This Row],[Rep Votes]] -> 128838342 | F30: =Table5[[#This Row],[Total Votes]]/Table5[[#This Row],[Population]] -> 0.39895442 | G30: =IFERROR((Table5[[#This Row],[T% of Pop]]-F29)/F29,"-") -> -0.012971548 | H30: =(Table5[[#This Row],[T% of Pop]]-$R$17)/$R$18 -> 0.72790262 | I30: =Table5[[#This Row],[Dem Votes]]/Table5[[#This Row],[Population]] -> 0.20391873 | J30: =(Table5[[#This Row],[D% of Pop]]-$Q$6)/$Q$7 -> 0.79906293 | K30: =IFERROR(Table5[[#This Row],[D%Z-Score2]]-J29,"-") -> -0.18959081 | L30: =Table5[[#This Row],[Rep Votes]]/Table5[[#This Row],[Population]] -> 0.1950357 | M30: =Table5[[#This Row],[Rep Votes]]/Table5[[#This Row],[Population]] -> 0.1950357 | N30: =(Table5[[#This Row],[R% of Pop2]]-$T$6)/$T$7 -> 0.30733763 | O30: =IFERROR(Table5[[#This Row],[R%Z-Score]]-N29,"-") -> 0.021461185 | Q30: =_xlfn.QUARTILE.INC(Table5[Column3],1) -> -0.054065333
A31: 2020 | B31: 331530000 | C31: 81283501 | D31: 74223975 | E31: =Table5[[#This Row],[Dem Votes]]+Table5[[#This Row],[Rep Votes]] -> 155507476 | F31: =Table5[[#This Row],[Total Votes]]/Table5[[#This Row],[Population]] -> 0.46906004 | G31: =IFERROR((Table5[[#This Row],[T% of Pop]]-F30)/F30,"-") -> 0.17572337 | H31: =(Table5[[#This Row],[T% of Pop]]-$R$17)/$R$18 -> 2.0598249 | I31: =Table5[[#This Row],[Dem Votes]]/Table5[[#This Row],[Population]] -> 0.24517691 | J31: =(Table5[[#This Row],[D% of Pop]]-$Q$6)/$Q$7 -> 2.0776343 | K31: =IFERROR(Table5[[#This Row],[D%Z-Score2]]-J30,"-") -> 1.2785714 | L31: =Table5[[#This Row],[Rep Votes]]/Table5[[#This Row],[Population]] -> 0.22388313 | M31: =Table5[[#This Row],[Rep Votes]]/Table5[[#This Row],[Population]] -> 0.22388313 | N31: =(Table5[[#This Row],[R% of Pop2]]-$T$6)/$T$7 -> 1.0150158 | O31: =IFERROR(Table5[[#This Row],[R%Z-Score]]-N30,"-") -> 0.7076782 | Q31: =_xlfn.QUARTILE.INC(Table5[Column3],3) -> 0.12958134
A32: 2024 | B32: 337200000 | C32: 71239855 | D32: 74834590 | E32: =Table5[[#This Row],[Dem Votes]]+Table5[[#This Row],[Rep Votes]] -> 146074445 | F32: =Table5[[#This Row],[Total Votes]]/Table5[[#This Row],[Population]] -> 0.43319824 | G32: =IFERROR((Table5[[#This Row],[T% of Pop]]-F31)/F31,"-") -> -0.07645462 | H32: =(Table5[[#This Row],[T% of Pop]]-$R$17)/$R$18 -> 1.3784938 | I32: =Table5[[#This Row],[Dem Votes]]/Table5[[#This Row],[Population]] -> 0.21126885 | J32: =(Table5[[#This Row],[D% of Pop]]-$Q$6)/$Q$7 -> 1.0268396 | K32: =IFERROR(Table5[[#This Row],[D%Z-Score2]]-J31,"-") -> -1.0507947 | L32: =Table5[[#This Row],[Rep Votes]]/Table5[[#This Row],[Population]] -> 0.22192939 | M32: =Table5[[#This Row],[Rep Votes]]/Table5[[#This Row],[Population]] -> 0.22192939 | N32: =(Table5[[#This Row],[R% of Pop2]]-$T$6)/$T$7 -> 0.96708706 | O32: =IFERROR(Table5[[#This Row],[R%Z-Score]]-N31,"-") -> -0.047928759
P33: min | Q33: =MIN(Table5[Column3]) -> -0.28438069
P34: max | Q34: =MAX(Table5[Column3]) -> 0.36996936
P35: iqr | Q35: =Q31-Q30 -> 0.18364667
P36: uf | Q36: =Q31+(1.5*Q35) -> 0.40505134

Sheet 1972-2024
A1: Year | B1: Population | C1: Dem Votes | D1: Rep Votes | E1: Total Votes | F1: T% of Pop | G1: T Probability | H1: D% of Pop | I1: D Probability | J1: D%Z-Score | K1: DZ Dif | L1: R% of Pop | M1: R Probability | N1: R%Z-Score | O1: RZ Dif | Q1: D | T1: R
A2: 1972 | B2: 209900000 | C2: 29173222 | D2: 47168710 | E2: =Table6[[#This Row],[Rep Votes]]+Table6[[#This Row],[Dem Votes]] -> 76341932 | F2: =Table6[[#This Row],[Total Votes]]/Table6[[#This Row],[Population]] -> 0.3637062 | G2: =1-_xlfn.NORM.DIST(Table6[[#This Row],[T% of Pop]],$R$25,$R$26,TRUE) -> 0.69742761 | H2: 0.13898629 | I2: =1-_xlfn.NORM.DIST(Table6[[#This Row],[D% of Pop]],$R$13,$R$14,TRUE) -> 0.95543488 | J2: =(Table6[[#This Row],[D% of Pop]]-$R$13)/$R$14 -> -1.7000037 | K2: =IFERROR((Table6[[#This Row],[D%Z-Score]]-J1),"-") -> - | L2: 0.22471991 | M2: =1-_xlfn.NORM.DIST(Table6[[#This Row],[R% of Pop]],$U$13,$U$14,TRUE) -> 0.12953982 | N2: =(Table6[[#This Row],[R% of Pop]]-$U$13)/$U$14 -> 1.1285691 | O2: =IFERROR(Table6[[#This Row],[R%Z-Score]]-N1,"-") -> - | Q2: Mean | R2: =AVERAGE(Table6[Dem Votes]) -> 52928832 | T2: Mean | U2: =AVERAGE(Table6[Rep Votes]) -> 54091892
A3: 1976 | B3: 218040000 | C3: 40831881 | D3: 39148634 | E3: =Table6[[#This Row],[Rep Votes]]+Table6[[#This Row],[Dem Votes]] -> 79980515 | F3: =Table6[[#This Row],[Total Votes]]/Table6[[#This Row],[Population]] -> 0.36681579 | G3: =1-_xlfn.NORM.DIST(Table6[[#This Row],[T% of Pop]],$R$25,$R$26,TRUE) -> 0.67096259 | H3: 0.18726785 | I3: =1-_xlfn.NORM.DIST(Table6[[#This Row],[D% of Pop]],$R$13,$R$14,TRUE) -> 0.51317319 | J3: =(Table6[[#This Row],[D% of Pop]]-$R$13)/$R$14 -> -0.033026289 | K3: =IFERROR((Table6[[#This Row],[D%Z-Score]]-J2),"-") -> 1.6669774 | L3: 0.17954795 | M3: =1-_xlfn.NORM.DIST(Table6[[#This Row],[R% of Pop]],$U$13,$U$14,TRUE) -> 0.73879794 | N3: =(Table6[[#This Row],[R% of Pop]]-$U$13)/$U$14 -> -0.63964392 | O3: =IFERROR(Table6[[#This Row],[R%Z-Score]]-N2,"-") -> -1.768213 | Q3: SD | R3: =_xlfn.STDEV.S(Table6[Dem Votes]) -> 15835025 | T3: SD | U3: =_xlfn.STDEV.S(Table6[Rep Votes]) -> 12155669
A4: 1980 | B4: 227220000 | C4: 35481115 | D4: 43903230 | E4: =Table6[[#This Row],[Rep Votes]]+Table6[[#This Row],[Dem Votes]] -> 79384345 | F4: =Table6[[#This Row],[Total Votes]]/Table6[[#This Row],[Population]] -> 0.34937217 | G4: =1-_xlfn.NORM.DIST(Table6[[#This Row],[T% of Pop]],$R$25,$R$26,TRUE) -> 0.80515322 | H4: 0.15615313 | I4: =1-_xlfn.NORM.DIST(Table6[[#This Row],[D% of Pop]],$R$13,$R$14,TRUE) -> 0.86591749 | J4: =(Table6[[#This Row],[D% of Pop]]-$R$13)/$R$14 -> -1.1072982 | K4: =IFERROR((Table6[[#This Row],[D%Z-Score]]-J3),"-") -> -1.0742719 | L4: 0.19321904 | M4: =1-_xlfn.NORM.DIST(Table6[[#This Row],[R% of Pop]],$U$13,$U$14,TRUE) -> 0.54161458 | N4: =(Table6[[#This Row],[R% of Pop]]-$U$13)/$U$14 -> -0.10450219 | O4: =IFERROR(Table6[[#This Row],[R%Z-Score]]-N3,"-") -> 0.53514173 | Q4: Q1 | R4: =_xlfn.QUARTILE.INC(Table6[Dem Votes],1) -> 41076280 | T4: Q1 | U4: =_xlfn.QUARTILE.INC(Table6[Rep Votes],1) -> 44719600
A5: 1984 | B5: 235820000 | C5: 37577352 | D5: 54455472 | E5: =Table6[[#This Row],[Rep Votes]]+Table6[[#This Row],[Dem Votes]] -> 92032824 | F5: =Table6[[#This Row],[Total Votes]]/Table6[[#This Row],[Population]] -> 0.39026725 | G5: =1-_xlfn.NORM.DIST(Table6[[#This Row],[T% of Pop]],$R$25,$R$26,TRUE) -> 0.45269482 | H5: 0.1593476 | I5: =1-_xlfn.NORM.DIST(Table6[[#This Row],[D% of Pop]],$R$13,$R$14,TRUE) -> 0.84061905 | J5: =(Table6[[#This Row],[D% of Pop]]-$R$13)/$R$14 -> -0.99700536 | K5: =IFERROR((Table6[[#This Row],[D%Z-Score]]-J4),"-") -> 0.11029284 | L5: 0.23091965 | M5: =1-_xlfn.NORM.DIST(Table6[[#This Row],[R% of Pop]],$U$13,$U$14,TRUE) -> 0.085148238 | N5: =(Table6[[#This Row],[R% of Pop]]-$U$13)/$U$14 -> 1.3712518 | O5: =IFERROR(Table6[[#This Row],[R%Z-Score]]-N4,"-") -> 1.475754 | Q5: Q3 | R5: =_xlfn.QUARTILE.INC(Table6[Dem Votes],3) -> 65900225 | T5: Q3 | U5: =_xlfn.QUARTILE.INC(Table6[Rep Votes],3) -> 61763834
A6: 1988 | B6: 244500000 | C6: 41809476 | D6: 48886597 | E6: =Table6[[#This Row],[Rep Votes]]+Table6[[#This Row],[Dem Votes]] -> 90696073 | F6: =Table6[[#This Row],[Total Votes]]/Table6[[#This Row],[Population]] -> 0.37094508 | G6: =1-_xlfn.NORM.DIST(Table6[[#This Row],[T% of Pop]],$R$25,$R$26,TRUE) -> 0.63447057 | H6: 0.1709999 | I6: =1-_xlfn.NORM.DIST(Table6[[#This Row],[D% of Pop]],$R$13,$R$14,TRUE) -> 0.72397669 | J6: =(Table6[[#This Row],[D% of Pop]]-$R$13)/$R$14 -> -0.59469612 | K6: =IFERROR((Table6[[#This Row],[D%Z-Score]]-J5),"-") -> 0.40230924 | L6: 0.19994518 | M6: =1-_xlfn.NORM.DIST(Table6[[#This Row],[R% of Pop]],$U$13,$U$14,TRUE) -> 0.43691867 | N6: =(Table6[[#This Row],[R% of Pop]]-$U$13)/$U$14 -> 0.15878618 | O6: =IFERROR(Table6[[#This Row],[R%Z-Score]]-N5,"-") -> -1.2124656 | Q6: IQR | R6: =R5-R4 -> 24823945 | T6: IQR | U6: =U5-U4 -> 17044234
A7: 1992 | B7: 256510000 | C7: 44909889 | D7: 39104550 | E7: =Table6[[#This Row],[Rep Votes]]+Table6[[#This Row],[Dem Votes]] -> 84014439 | F7: =Table6[[#This Row],[Total Votes]]/Table6[[#This Row],[Population]] -> 0.3275289 | G7: =1-_xlfn.NORM.DIST(Table6[[#This Row],[T% of Pop]],$R$25,$R$26,TRUE) -> 0.91668312 | H7: 0.17508046 | I7: =1-_xlfn.NORM.DIST(Table6[[#This Row],[D% of Pop]],$R$13,$R$14,TRUE) -> 0.67501722 | J7: =(Table6[[#This Row],[D% of Pop]]-$R$13)/$R$14 -> -0.45381003 | K7: =IFERROR((Table6[[#This Row],[D%Z-Score]]-J6),"-") -> 0.14088608 | L7: 0.15244844 | M7: =1-_xlfn.NORM.DIST(Table6[[#This Row],[R% of Pop]],$U$13,$U$14,TRUE) -> 0.95547475 | N7: =(Table6[[#This Row],[R% of Pop]]-$U$13)/$U$14 -> -1.7004278 | O7: =IFERROR(Table6[[#This Row],[R%Z-Score]]-N6,"-") -> -1.8592139 | Q7: UF | R7: =R5+(1.5*R6) -> 1.0313614e+08 | T7: UF | U7: =U5+(1.5*U6) -> 87330184
A8: 1996 | B8: 269390000 | C8: 47401185 | D8: 39197469 | E8: =Table6[[#This Row],[Rep Votes]]+Table6[[#This Row],[Dem Votes]] -> 86598654 | F8: =Table6[[#This Row],[Total Votes]]/Table6[[#This Row],[Population]] -> 0.32146202 | G8: =1-_xlfn.NORM.DIST(Table6[[#This Row],[T% of Pop]],$R$25,$R$26,TRUE) -> 0.93678627 | H8: 0.17595748 | I8: =1-_xlfn.NORM.DIST(Table6[[#This Row],[D% of Pop]],$R$13,$R$14,TRUE) -> 0.66404569 | J8: =(Table6[[#This Row],[D% of Pop]]-$R$13)/$R$14 -> -0.42352999 | K8: =IFERROR((Table6[[#This Row],[D%Z-Score]]-J7),"-") -> 0.030280048 | L8: 0.14550454 | M8: =1-_xlfn.NORM.DIST(Table6[[#This Row],[R% of Pop]],$U$13,$U$14,TRUE) -> 0.97570889 | N8: =(Table6[[#This Row],[R% of Pop]]-$U$13)/$U$14 -> -1.97224 | O8: =IFERROR(Table6[[#This Row],[R%Z-Score]]-N7,"-") -> -0.27181221 | Q8: Min | R8: =MIN(Table6[Dem Votes]) -> 29173222 | T8: Min | U8: =MIN(Table6[Rep Votes]) -> 39104550
A9: 2000 | B9: 282160000 | C9: 50999897 | D9: 50456002 | E9: =Table6[[#This Row],[Rep Votes]]+Table6[[#This Row],[Dem Votes]] -> 101455899 | F9: =Table6[[#This Row],[Total Votes]]/Table6[[#This Row],[Population]] -> 0.35956868 | G9: =1-_xlfn.NORM.DIST(Table6[[#This Row],[T% of Pop]],$R$25,$R$26,TRUE) -> 0.73107539 | H9: 0.18074815 | I9: =1-_xlfn.NORM.DIST(Table6[[#This Row],[D% of Pop]],$R$13,$R$14,TRUE) -> 0.60184538 | J9: =(Table6[[#This Row],[D% of Pop]]-$R$13)/$R$14 -> -0.25812654 | K9: =IFERROR((Table6[[#This Row],[D%Z-Score]]-J8),"-") -> 0.16540345 | L9: 0.17882053 | M9: =1-_xlfn.NORM.DIST(Table6[[#This Row],[R% of Pop]],$U$13,$U$14,TRUE) -> 0.74797077 | N9: =(Table6[[#This Row],[R% of Pop]]-$U$13)/$U$14 -> -0.66811772 | O9: =IFERROR(Table6[[#This Row],[R%Z-Score]]-N8,"-") -> 1.3041222 | Q9: Max | R9: =MAX(Table6[Dem Votes]) -> 81283501 | T9: Max | U9: =MAX(Table6[Rep Votes]) -> 74834590
A10: 2004 | B10: 292810000 | C10: 59028444 | D10: 62040610 | E10: =Table6[[#This Row],[Rep Votes]]+Table6[[#This Row],[Dem Votes]] -> 121069054 | F10: =Table6[[#This Row],[Total Votes]]/Table6[[#This Row],[Population]] -> 0.41347308 | G10: =1-_xlfn.NORM.DIST(Table6[[#This Row],[T% of Pop]],$R$25,$R$26,TRUE) -> 0.25002734 | H10: 0.20159299 | I10: =1-_xlfn.NORM.DIST(Table6[[#This Row],[D% of Pop]],$R$13,$R$14,TRUE) -> 0.32219622 | J10: =(Table6[[#This Row],[D% of Pop]]-$R$13)/$R$14 -> 0.4615662 | K10: =IFERROR((Table6[[#This Row],[D%Z-Score]]-J9),"-") -> 0.71969274 | L10: 0.21188009 | M10: =1-_xlfn.NORM.DIST(Table6[[#This Row],[R% of Pop]],$U$13,$U$14,TRUE) -> 0.26566838 | N10: =(Table6[[#This Row],[R% of Pop]]-$U$13)/$U$14 -> 0.62596673 | O10: =IFERROR(Table6[[#This Row],[R%Z-Score]]-N9,"-") -> 1.2940844
A11: 2008 | B11: 304090000 | C11: 69498516 | D11: 59948323 | E11: =Table6[[#This Row],[Rep Votes]]+Table6[[#This Row],[Dem Votes]] -> 129446839 | F11: =Table6[[#This Row],[Total Votes]]/Table6[[#This Row],[Population]] -> 0.42568594 | G11: =1-_xlfn.NORM.DIST(Table6[[#This Row],[T% of Pop]],$R$25,$R$26,TRUE) -> 0.16682706 | H11: 0.22854588 | I11: =1-_xlfn.NORM.DIST(Table6[[#This Row],[D% of Pop]],$R$13,$R$14,TRUE) -> 0.081939067 | J11: =(Table6[[#This Row],[D% of Pop]]-$R$13)/$R$14 -> 1.3921462 | K11: =IFERROR((Table6[[#This Row],[D%Z-Score]]-J10),"-") -> 0.93057999 | L11: 0.19714007 | M11: =1-_xlfn.NORM.DIST(Table6[[#This Row],[R% of Pop]],$U$13,$U$14,TRUE) -> 0.48046655 | N11: =(Table6[[#This Row],[R% of Pop]]-$U$13)/$U$14 -> 0.04898267 | O11: =IFERROR(Table6[[#This Row],[R%Z-Score]]-N10,"-") -> -0.57698406
A12: 2012 | B12: 313830000 | C12: 65915795 | D12: 60933504 | E12: =Table6[[#This Row],[Rep Votes]]+Table6[[#This Row],[Dem Votes]] -> 126849299 | F12: =Table6[[#This Row],[Total Votes]]/Table6[[#This Row],[Population]] -> 0.40419749 | G12: =1-_xlfn.NORM.DIST(Table6[[#This Row],[T% of Pop]],$R$25,$R$26,TRUE) -> 0.32550992 | H12: 0.21003663 | I12: =1-_xlfn.NORM.DIST(Table6[[#This Row],[D% of Pop]],$R$13,$R$14,TRUE) -> 0.22569712 | J12: =(Table6[[#This Row],[D% of Pop]]-$R$13)/$R$14 -> 0.75309264 | K12: =IFERROR((Table6[[#This Row],[D%Z-Score]]-J11),"-") -> -0.63905355 | L12: 0.19416086 | M12: =1-_xlfn.NORM.DIST(Table6[[#This Row],[R% of Pop]],$U$13,$U$14,TRUE) -> 0.52696204 | N12: =(Table6[[#This Row],[R% of Pop]]-$U$13)/$U$14 -> -0.067635347 | O12: =IFERROR(Table6[[#This Row],[R%Z-Score]]-N11,"-") -> -0.11661802 | Q12: D | T12: R
